Workbook

Sheet Planilha2

Sheet Controle CIT
B2: Data | C2: PLACA | D2: VOLUME | E2: VIAGENS | F2: TOTAL | G2: OBSERVAÇÕES
B3: 46076 | C3: NPB-4686 | D3: 20000 | E3: - | F3: =IFERROR(Tabela24[[#This Row],[VOLUME]]*Tabela24[[#This Row],[VIAGENS]],"")
B4: 46076 | C4: QZN-8E65 | D4: 20000 | E4: 1 | F4: =IFERROR(Tabela24[[#This Row],[VOLUME]]*Tabela24[[#This Row],[VIAGENS]],"") -> 20000 | G4: P/ VIAGEM
B5: 46076 | C5: TAB-2G94 | D5: 20000 | E5: 3 | F5: =IFERROR(Tabela24[[#This Row],[VOLUME]]*Tabela24[[#This Row],[VIAGENS]],"") -> 60000 | G5: P/ GARAGEM CARREGADO
B6: 46076 | C6: PHO-4D02 | D6: 25000 | E6: - | F6: =IFERROR(Tabela24[[#This Row],[VOLUME]]*Tabela24[[#This Row],[VIAGENS]],"")
B7: 46076 | C7: PHO-4D32 | D7: 25000 | E7: 2 | F7: =IFERROR(Tabela24[[#This Row],[VOLUME]]*Tabela24[[#This Row],[VIAGENS]],"") -> 50000 | G7: CARREGADO COM 15M
B8: 46076 | C8: PHZ-8J44 | D8: 25000 | E8: 2 | F8: =IFERROR(Tabela24[[#This Row],[VOLUME]]*Tabela24[[#This Row],[VIAGENS]],"") -> 50000
B9: 46076 | C9: OAK-8G51 | D9: 25000 | E9: 2 | F9: =IFERROR(Tabela24[[#This Row],[VOLUME]]*Tabela24[[#This Row],[VIAGENS]],"") -> 50000
B10: 46076 | C10: QZW-6A95 | D10: 25000 | E10: 2 | F10: =IFERROR(Tabela24[[#This Row],[VOLUME]]*Tabela24[[#This Row],[VIAGENS]],"") -> 50000
B11: 46076 | C11: JXA-4749 | D11: 30000 | E11: - | F11: =IFERROR(Tabela24[[#This Row],[VOLUME]]*Tabela24[[#This Row],[VIAGENS]],"")
B12: 46076 | C12: JXA-5543 | D12: 30000 | E12: 2 | F12: =IFERROR(Tabela24[[#This Row],[VOLUME]]*Tabela24[[#This Row],[VIAGENS]],"") -> 60000
B13: 46076 | C13: JXA-5463 | D13: 30000 | E13: 1 | F13: =IFERROR(Tabela24[[#This Row],[VOLUME]]*Tabela24[[#This Row],[VIAGENS]],"") -> 30000 | G13: NÃO TINHA PEDIDO
B14: Total | F14: =SUM(Tabela24[TOTAL]) -> 370000
B15: 46077 | C15: NPB-4686 | D15: 20000 | E15: - | F15: =IFERROR(D15*E15,"") | I15: Data | J15: PLACA | K15: VOLUME | L15: VIAGENS | M15: TOTAL | N15: OBSERVAÇÕES
B16: 46077 | C16: QZN-8E65 | D16: 20000 | E16: 1 | F16: =IFERROR(D16*E16,"") -> 20000 | G16: CT ADICIONAL, CHEGADA AS 10 HORAS. CT COM OCORRÊNCIA NO POSTO BBX | I16: 46077 | J16: NOM-7B05 | K16: 20000 | L16: 2 | M16: =IFERROR(#REF!*#REF!,"") | N16: TRANSCAP
B17: 46077 | C17: TAB-2G94 | D17: 20000 | E17: 2 | F17: =IFERROR(D17*E17,"") -> 40000 | I17: 46077 | J17: QZR-7E86 | K17: 35000 | L17: 1 | M17: =IFERROR(#REF!*#REF!,"") | N17: IN TEIXEIRA
B18: 46077 | C18: PHO-4D02 | D18: 25000 | E18: - | F18: =IFERROR(D18*E18,"") | I18: Total | M18: =SUM(M16:M17) -> 0
B19: 46077 | C19: PHO-4D32 | D19: 25000 | E19: 2 | F19: =IFERROR(D19*E19,"") -> 50000
B20: 46077 | C20: PHZ-8J44 | D20: 25000 | E20: 2 | F20: =IFERROR(D20*E20,"") -> 50000
B21: 46077 | C21: OAK-8G51 | D21: 25000 | E21: 2 | F21: =IFERROR(D21*E21,"") -> 50000
B22: 46077 | C22: QZW-6A95 | D22: 25000 | E22: 2 | F22: =IFERROR(D22*E22,"") -> 50000
B23: 46077 | C23: JXA-4749 | D23: 30000 | E23: - | F23: =IFERROR(D23*E23,"")
B24: 46077 | C24: JXA-5543 | D24: 30000 | E24: 2 | F24: =IFERROR(D24*E24,"") -> 60000
B25: 46077 | C25: JXA-5463 | D25: 30000 | E25: 1 | F25: =IFERROR(D25*E25,"") -> 30000 | G25: VIAGEM
B26: Total | F26: =SUM(F15:F25) -> 350000
B27: 46078 | C27: NPB-4686 | D27: 20000 | E27: - | F27: =IFERROR(D27*E27,"") | I27: Data | J27: PLACA | K27: VOLUME | L27: VIAGENS | M27: TOTAL | N27: OBSERVAÇÕES
B28: 46078 | C28: QZN-8E65 | D28: 20000 | E28: 1 | F28: =IFERROR(D28*E28,"") -> 20000 | G28: CT adicional | I28: 46077 | J28: NOM-7B05 | K28: 20000 | L28: 1 | M28: =IFERROR(#REF!*#REF!,"") | N28: TRANSCAP
B29: 46078 | C29: TAB-2G94 | D29: 20000 | E29: 2 | F29: =IFERROR(D29*E29,"") -> 40000 | I29: 46077 | J29: QZR-7E86 | K29: 35000 | L29: 1 | M29: =IFERROR(#REF!*#REF!,"") | N29: IN TEIXEIRA
B30: 46078 | C30: PHO-4D02 | D30: 25000 | E30: - | F30: =IFERROR(D30*E30,"") | I30: Total | M30: =SUM(M28:M29) -> 0
B31: 46078 | C31: PHO-4D32 | D31: 25000 | E31: 2 | F31: =IFERROR(D31*E31,"") -> 50000
B32: 46078 | C32: PHZ-8J44 | D32: 25000 | E32: 3 | F32: =IFERROR(D32*E32,"") -> 75000 | G32: Garagem com a viagem
B33: 46078 | C33: OAK-8G51 | D33: 25000 | E33: 2 | F33: =IFERROR(D33*E33,"") -> 50000
B34: 46078 | C34: QZW-6A95 | D34: 25000 | E34: 2 | F34: =IFERROR(D34*E34,"") -> 50000 | G34: Garagem com 15m³
B35: 46078 | C35: JXA-4749 | D35: 30000 | E35: - | F35: =IFERROR(D35*E35,"")
B36: 46078 | C36: JXA-5543 | D36: 30000 | E36: 1 | F36: =IFERROR(D36*E36,"") -> 30000 | G36: Descarregar o ODM do PJB
B37: 46078 | C37: JXA-5463 | D37: 30000 | E37: - | F37: =IFERROR(D37*E37,"")
F38: =SUM(F27:F37) -> 315000
B39: 46079 | C39: NPB-4686 | D39: 20000 | E39: - | F39: =IFERROR(D39*E39,"") | I39: Data | J39: PLACA | K39: VOLUME | L39: VIAGENS | M39: TOTAL | N39: OBSERVAÇÕES
B40: 46079 | C40: QZN-8E65 | D40: 20000 | E40: 1 | F40: =IFERROR(D40*E40,"") -> 20000 | G40: CT saiu com consumo. Saída s 08:38 e finalizou as 16:16. CT não retornou pois o pneu furou. | I40: 46079 | J40: NOM-7B05 | K40: 20000 | L40: 2 | M40: =IFERROR(K40*L40,"") -> 40000 | N40: TRANSCAP
B41: 46079 | C41: TAB-2G94 | D41: 20000 | E41: 2 | F41: =IFERROR(D41*E41,"") -> 40000 | I41: 46079 | J41: QZR-7E86 | K41: 35000 | L41: 1 | M41: =IFERROR(K41*L41,"") -> 35000 | N41: IN TEIXEIRA
...

Sheet Planilha1
B1: Adriano Paz | C1: PLACA | D1: CAPACIDADE | E1: VIAGEM | F1: TOTAL
B2: Alessandro Souza | C2: OAK-8G51 | D2: 25000 | F2: =E2*D2 -> 0
B3: Benedito Gomes | C3: QZW-6A95 | D3: 25000 | F3: =E3*D3 -> 0
B4: Caio Victor Pessoa | C4: PHO-4D02 | D4: 25000 | F4: =E4*D4 -> 0
B5: Carlos Alberto Noronha | C5: PHZ-8J44 | D5: 25000 | F5: =E5*D5 -> 0
B6: Daiton De Lima Costa | C6: PHO-4D32 | D6: 25000 | F6: =E6*D6 -> 0
B7: Edney Freitas | C7: JXA-5473 | D7: 30000 | F7: =E7*D7 -> 0
B8: Fabricio Silva E Silva | C8: JXA-5543 | D8: 30000 | F8: =E8*D8 -> 0
B9: Ismael Souza Da Silva | C9: JXA-4749 | D9: 30000 | F9: =E9*D9 -> 0
B10: Luiz Santos Amaral | C10: TAB-2G94 | D10: 20000 | F10: =E10*D10 -> 0
B11: Paulo Sergio Cordeiro | C11: NPB-4686 | D11: 20000 | F11: =E11*D11 -> 0
B12: Rogerio Moraes Da Silva | C12: QZN-8E65 | D12: 20000 | F12: =E12*D12 -> 0
B13: Wilmar Leao Filho | F13: =SUM(F2:F12) -> 0
B14: Raimundo Oderclei Cruz | E14: =_xlfn.XLOOKUP(B14,'Controle de CT'!B:B,'Controle de CT'!O:O,"")
B15: Ewertom Melo | E15: =_xlfn.XLOOKUP(B15,'Controle de CT'!B:B,'Controle de CT'!O:O,"")
B16: Adriano Paz | E16: =_xlfn.XLOOKUP(B16,'Controle de CT'!B:B,'Controle de CT'!O:O,"")
B17: Ronaldo Macena | E17: =_xlfn.XLOOKUP(B17,'Controle de CT'!B:B,'Controle de CT'!O:O,"")

Sheet Controle de CT
Q2: =TODAY() -> 46165
A3: Situação | B3: CIF | C3: FOB | D3: Transferência | E3: RZD | F3: Total FOB | G3: Totais
A4: Aguardando Entrada | B4: =COUNTIFS(Tabela1[Status],A4,Tabela1[Tipo de Frete],B3,Tabela1[Data],Q2) -> 2 | C4: =COUNTIFS(Tabela1[Status],A4,Tabela1[Tipo de Frete],C3,Tabela1[Data],Q2) -> 1 | D4: =COUNTIFS(Tabela1[Status],A4,Tabela1[Tipo de Frete],D3,Tabela1[Data],Q2) -> 0 | E4: =COUNTIFS(Tabela1[Status],A4,Tabela1[Tipo de Frete],E3,Tabela1[Data],Q2) -> 0 | F4: =SUM(C4,D4,E4) -> 1 | G4: =SUM(B4:E4) -> 3
A5: Fila de Carregamento | B5: =COUNTIFS(Tabela1[Status],A5,Tabela1[Tipo de Frete],B3,Tabela1[Data],Q2) -> 1 | C5: =COUNTIFS(Tabela1[Status],A5,Tabela1[Tipo de Frete],C3,Tabela1[Data],Q2) -> 1 | D5: =COUNTIFS(Tabela1[Status],A5,Tabela1[Tipo de Frete],D3,Tabela1[Data],Q2) -> 0 | E5: =COUNTIFS(Tabela1[Status],A5,Tabela1[Tipo de Frete],E3,Tabela1[Data],Q2) -> 0 | F5: =SUM(C5,D5,E5) -> 1 | G5: =SUM(B5:E5) -> 2
A6: Finalizado | B6: =COUNTIFS(Tabela1[Status],A6,Tabela1[Tipo de Frete],B3,Tabela1[Data],Q2) -> 1 | C6: =COUNTIFS(Tabela1[Status],A6,Tabela1[Tipo de Frete],C3,Tabela1[Data],Q2) -> 0 | D6: =COUNTIFS(Tabela1[Status],A6,Tabela1[Tipo de Frete],D3,Tabela1[Data],Q2) -> 0 | E6: =COUNTIFS(Tabela1[Status],A6,Tabela1[Tipo de Frete],E3,Tabela1[Data],Q2) -> 0 | F6: =SUM(C6,D6,E6) -> 0 | G6: =SUM(B6:D6) -> 1
A8: NÃO MEXER NA FÓRMULA ACIMA | K8: Data | L8: Motorista | M8: Tipo de Frete | N8: Status | O8: Viagens | P8: Chegada | Q8: Entrada | R8: Saída | S8: Nota Fiscal | T8: Tempo de Carregamento | U8: Tempo Total | V8: Observação | W8: Coluna1 | X8: Coluna2
K9: 46063 | L9: Benedito Gomes | M9: =IF(Tabela1[[#This Row],[Motorista]]="","",IFERROR(_xlfn.XLOOKUP(Tabela1[[#This Row],[Motorista]],Base!A:A,Base!B:B),"")) -> CIF | N9: =IF(R9<>"","Finalizado", IF(Q9<>"","Fila de Carregamento", IF(P9<>"","Aguardando Entrada",""))) -> Finalizado | O9: =IF(Tabela1[[#This Row],[Motorista]]="","",IF(COUNTIFS(Tabela1[Data],Tabela1[[#This Row],[Data]],Tabela1[Motorista],Tabela1[[#This Row],[Motorista]])=1,"1 viagem",COUNTIFS(Tabela1[Data],Tabela1[[#This Row],[Data]],Tabela1[Motorista],Tabela1[[#This Row],[Motorista]])&" viagens")) -> 2 viagens | P9: 0.21875 | Q9: 0.22291667 | R9: 0.25069444 | S9: Impresso | T9: =IF(OR(Tabela1[[#This Row],[Entrada]]="",Tabela1[[#This Row],[Saída]]=""), "", Tabela1[[#This Row],[Saída]]-Tabela1[[#This Row],[Entrada]]) -> 0.027777778 | U9: =IF(OR('Controle de CT'!$R9= "", 'Controle de CT'!$P9= ""), "", 'Controle de CT'!$R9-'Controle de CT'!$P9) -> 0.031944444 | X9: Coluna2
K10: 46063 | L10: David dos Santos | M10: =IF(Tabela1[[#This Row],[Motorista]]="","",IFERROR(_xlfn.XLOOKUP(Tabela1[[#This Row],[Motorista]],Base!A:A,Base!B:B),"")) -> FOB | N10: =IF(R10<>"","Finalizado", IF(Q10<>"","Fila de Carregamento", IF(P10<>"","Aguardando Entrada",""))) -> Finalizado | O10: =IF(Tabela1[[#This Row],[Motorista]]="","",IF(COUNTIFS(Tabela1[Data],Tabela1[[#This Row],[Data]],Tabela1[Motorista],Tabela1[[#This Row],[Motorista]])=1,"1 viagem",COUNTIFS(Tabela1[Data],Tabela1[[#This Row],[Data]],Tabela1[Motorista],Tabela1[[#This Row],[Motorista]])&" viagens")) -> 2 viagens | P10: 0.23611111 | Q10: 0.2375 | R10: 0.28125 | S10: Impresso | T10: =IF(OR(Tabela1[[#This Row],[Entrada]]="",Tabela1[[#This Row],[Saída]]=""), "", Tabela1[[#This Row],[Saída]]-Tabela1[[#This Row],[Entrada]]) -> 0.04375 | U10: =IF(OR('Controle de CT'!$R10= "", 'Controle de CT'!$P10= ""), "", 'Controle de CT'!$R10-'Controle de CT'!$P10) -> 0.045138889
K11: 46063 | L11: Marielson De Oliveira | M11: =IF(Tabela1[[#This Row],[Motorista]]="","",IFERROR(_xlfn.XLOOKUP(Tabela1[[#This Row],[Motorista]],Base!A:A,Base!B:B),"")) -> FOB | N11: =IF(R11<>"","Finalizado", IF(Q11<>"","Fila de Carregamento", IF(P11<>"","Aguardando Entrada",""))) -> Finalizado | O11: =IF(Tabela1[[#This Row],[Motorista]]="","",IF(COUNTIFS(Tabela1[Data],Tabela1[[#This Row],[Data]],Tabela1[Motorista],Tabela1[[#This Row],[Motorista]])=1,"1 viagem",COUNTIFS(Tabela1[Data],Tabela1[[#This Row],[Data]],Tabela1[Motorista],Tabela1[[#This Row],[Motorista]])&" viagens")) -> 2 viagens | P11: 0.27083333 | Q11: 0.32916667 | R11: 0.36805556 | S11: Impresso | T11: =IF(OR(Tabela1[[#This Row],[Entrada]]="",Tabela1[[#This Row],[Saída]]=""), "", Tabela1[[#This Row],[Saída]]-Tabela1[[#This Row],[Entrada]]) -> 0.038888889 | U11: =IF(OR('Controle de CT'!$R11= "", 'Controle de CT'!$P11= ""), "", 'Controle de CT'!$R11-'Controle de CT'!$P11) -> 0.097222222
K12: 46063 | L12: Valdemir Ângelo de Moraes | M12: =IF(Tabela1[[#This Row],[Motorista]]="","",IFERROR(_xlfn.XLOOKUP(Tabela1[[#This Row],[Motorista]],Base!A:A,Base!B:B),"")) -> RZD | N12: =IF(R12<>"","Finalizado", IF(Q12<>"","Fila de Carregamento", IF(P12<>"","Aguardando Entrada",""))) -> Finalizado | O12: =IF(Tabela1[[#This Row],[Motorista]]="","",IF(COUNTIFS(Tabela1[Data],Tabela1[[#This Row],[Data]],Tabela1[Motorista],Tabela1[[#This Row],[Motorista]])=1,"1 viagem",COUNTIFS(Tabela1[Data],Tabela1[[#This Row],[Data]],Tabela1[Motorista],Tabela1[[#This Row],[Motorista]])&" viagens")) -> 1 viagem | P12: 0.275 | Q12: 0.30694444 | R12: 0.33333333 | S12: Impresso | T12: =IF(OR(Tabela1[[#This Row],[Entrada]]="",Tabela1[[#This Row],[Saída]]=""), "", Tabela1[[#This Row],[Saída]]-Tabela1[[#This Row],[Entrada]]) -> 0.026388889 | U12: =IF(OR('Controle de CT'!$R12= "", 'Controle de CT'!$P12= ""), "", 'Controle de CT'!$R12-'Controle de CT'!$P12) -> 0.058333333
K13: 46063 | L13: Raimundo Oderclei Cruz | M13: =IF(Tabela1[[#This Row],[Motorista]]="","",IFERROR(_xlfn.XLOOKUP(Tabela1[[#This Row],[Motorista]],Base!A:A,Base!B:B),"")) -> CIF | N13: =IF(R13<>"","Finalizado", IF(Q13<>"","Fila de Carregamento", IF(P13<>"","Aguardando Entrada",""))) -> Finalizado | O13: =IF(Tabela1[[#This Row],[Motorista]]="","",IF(COUNTIFS(Tabela1[Data],Tabela1[[#This Row],[Data]],Tabela1[Motorista],Tabela1[[#This Row],[Motorista]])=1,"1 viagem",COUNTIFS(Tabela1[Data],Tabela1[[#This Row],[Data]],Tabela1[Motorista],Tabela1[[#This Row],[Motorista]])&" viagens")) -> 1 viagem | P13: 0.29236111 | Q13: 0.31388889 | R13: 0.34375 | S13: Impresso | T13: =IF(OR(Tabela1[[#This Row],[Entrada]]="",Tabela1[[#This Row],[Saída]]=""), "", Tabela1[[#This Row],[Saída]]-Tabela1[[#This Row],[Entrada]]) -> 0.029861111 | U13: =IF(OR('Controle de CT'!$R13= "", 'Controle de CT'!$P13= ""), "", 'Controle de CT'!$R13-'Controle de CT'!$P13) -> 0.051388889
K14: 46063 | L14: Caio Victor Pessoa | M14: =IF(Tabela1[[#This Row],[Motorista]]="","",IFERROR(_xlfn.XLOOKUP(Tabela1[[#This Row],[Motorista]],Base!A:A,Base!B:B),"")) -> CIF | N14: =IF(R14<>"","Finalizado", IF(Q14<>"","Fila de Carregamento", IF(P14<>"","Aguardando Entrada",""))) -> Finalizado | O14: =IF(Tabela1[[#This Row],[Motorista]]="","",IF(COUNTIFS(Tabela1[Data],Tabela1[[#This Row],[Data]],Tabela1[Motorista],Tabela1[[#This Row],[Motorista]])=1,"1 viagem",COUNTIFS(Tabela1[Data],Tabela1[[#This Row],[Data]],Tabela1[Motorista],Tabela1[[#This Row],[Motorista]])&" viagens")) -> 1 viagem | P14: 0.31388889 | Q14: 0.32916667 | R14: 0.36805556 | S14: Impresso | T14: =IF(OR(Tabela1[[#This Row],[Entrada]]="",Tabela1[[#This Row],[Saída]]=""), "", Tabela1[[#This Row],[Saída]]-Tabela1[[#This Row],[Entrada]]) -> 0.038888889 | U14: =IF(OR('Controle de CT'!$R14= "", 'Controle de CT'!$P14= ""), "", 'Controle de CT'!$R14-'Controle de CT'!$P14) -> 0.054166667
K15: 46063 | L15: Jose Osvaldir Queiroz | M15: =IF(Tabela1[[#This Row],[Motorista]]="","",IFERROR(_xlfn.XLOOKUP(Tabela1[[#This Row],[Motorista]],Base!A:A,Base!B:B),"")) -> FOB | N15: =IF(R15<>"","Finalizado", IF(Q15<>"","Fila de Carregamento", IF(P15<>"","Aguardando Entrada",""))) -> Finalizado | O15: =IF(Tabela1[[#This Row],[Motorista]]="","",IF(COUNTIFS(Tabela1[Data],Tabela1[[#This Row],[Data]],Tabela1[Motorista],Tabela1[[#This Row],[Motorista]])=1,"1 viagem",COUNTIFS(Tabela1[Data],Tabela1[[#This Row],[Data]],Tabela1[Motorista],Tabela1[[#This Row],[Motorista]])&" viagens")) -> 2 viagens | P15: 0.31527778 | Q15: 0.37986111 | R15: 0.42430556 | S15: Impresso | T15: =IF(OR(Tabela1[[#This Row],[Entrada]]="",Tabela1[[#This Row],[Saída]]=""), "", Tabela1[[#This Row],[Saída]]-Tabela1[[#This Row],[Entrada]]) -> 0.044444444 | U15: =IF(OR('Controle de CT'!$R15= "", 'Controle de CT'!$P15= ""), "", 'Controle de CT'!$R15-'Controle de CT'!$P15) -> 0.10902778
K16: 46063 | L16: Julio Cesar dos Santos | M16: =IF(Tabela1[[#This Row],[Motorista]]="","",IFERROR(_xlfn.XLOOKUP(Tabela1[[#This Row],[Motorista]],Base!A:A,Base!B:B),"")) -> FOB | N16: =IF(R16<>"","Finalizado", IF(Q16<>"","Fila de Carregamento", IF(P16<>"","Aguardando Entrada",""))) -> Finalizado | O16: =IF(Tabela1[[#This Row],[Motorista]]="","",IF(COUNTIFS(Tabela1[Data],Tabela1[[#This Row],[Data]],Tabela1[Motorista],Tabela1[[#This Row],[Motorista]])=1,"1 viagem",COUNTIFS(Tabela1[Data],Tabela1[[#This Row],[Data]],Tabela1[Motorista],Tabela1[[#This Row],[Motorista]])&" viagens")) -> 1 viagem | P16: 0.32569444 | Q16: 0.37222222 | R16: 0.42708333 | S16: Impresso | T16: =IF(OR(Tabela1[[#This Row],[Entrada]]="",Tabela1[[#This Row],[Saída]]=""), "", Tabela1[[#This Row],[Saída]]-Tabela1[[#This Row],[Entrada]]) -> 0.054861111 | U16: =IF(OR('Controle de CT'!$R16= "", 'Controle de CT'!$P16= ""), "", 'Controle de CT'!$R16-'Controle de CT'!$P16) -> 0.10138889
K17: 46063 | L17: Kalebe Oliveira da Silva | M17: =IF(Tabela1[[#This Row],[Motorista]]="","",IFERROR(_xlfn.XLOOKUP(Tabela1[[#This Row],[Motorista]],Base!A:A,Base!B:B),"")) -> FOB | N17: =IF(R17<>"","Finalizado", IF(Q17<>"","Fila de Carregamento", IF(P17<>"","Aguardando Entrada",""))) -> Finalizado | O17: =IF(Tabela1[[#This Row],[Motorista]]="","",IF(COUNTIFS(Tabela1[Data],Tabela1[[#This Row],[Data]],Tabela1[Motorista],Tabela1[[#This Row],[Motorista]])=1,"1 viagem",COUNTIFS(Tabela1[Data],Tabela1[[#This Row],[Data]],Tabela1[Motorista],Tabela1[[#This Row],[Motorista]])&" viagens")) -> 2 viagens | P17: 0.33958333 | Q17: 0.30347222 | R17: 0.41666667 | S17: Impresso | T17: =IF(OR(Tabela1[[#This Row],[Entrada]]="",Tabela1[[#This Row],[Saída]]=""), "", Tabela1[[#This Row],[Saída]]-Tabela1[[#This Row],[Entrada]]) -> 0.11319444 | U17: =IF(OR('Controle de CT'!$R17= "", 'Controle de CT'!$P17= ""), "", 'Controle de CT'!$R17-'Controle de CT'!$P17) -> 0.077083333
K18: 46063 | L18: Said Pereira Rabelo | M18: =IF(Tabela1[[#This Row],[Motorista]]="","",IFERROR(_xlfn.XLOOKUP(Tabela1[[#This Row],[Motorista]],Base!A:A,Base!B:B),"")) -> FOB | N18: =IF(R18<>"","Finalizado", IF(Q18<>"","Fila de Carregamento", IF(P18<>"","Aguardando Entrada",""))) -> Finalizado | O18: =IF(Tabela1[[#This Row],[Motorista]]="","",IF(COUNTIFS(Tabela1[Data],Tabela1[[#This Row],[Data]],Tabela1[Motorista],Tabela1[[#This Row],[Motorista]])=1,"1 viagem",COUNTIFS(Tabela1[Data],Tabela1[[#This Row],[Data]],Tabela1[Motorista],Tabela1[[#This Row],[Motorista]])&" viagens")) -> 1 viagem | P18: 0.34097222 | Q18: 0.37986111 | R18: 0.43055556 | S18: Impresso | T18: =IF(OR(Tabela1[[#This Row],[Entrada]]="",Tabela1[[#This Row],[Saída]]=""), "", Tabela1[[#This Row],[Saída]]-Tabela1[[#This Row],[Entrada]]) -> 0.050694444 | U18: =IF(OR('Controle de CT'!$R18= "", 'Controle de CT'!$P18= ""), "", 'Controle de CT'!$R18-'Controle de CT'!$P18) -> 0.089583333
K19: 46063 | L19: Andre Pereira de Oliveira | M19: =IF(Tabela1[[#This Row],[Motorista]]="","",IFERROR(_xlfn.XLOOKUP(Tabela1[[#This Row],[Motorista]],Base!A:A,Base!B:B),"")) -> FOB | N19: =IF(R19<>"","Finalizado", IF(Q19<>"","Fila de Carregamento", IF(P19<>"","Aguardando Entrada",""))) -> Finalizado | O19: =IF(Tabela1[[#This Row],[Motorista]]="","",IF(COUNTIFS(Tabela1[Data],Tabela1[[#This Row],[Data]],Tabela1[Motorista],Tabela1[[#This Row],[Motorista]])=1,"1 viagem",COUNTIFS(Tabela1[Data],Tabela1[[#This Row],[Data]],Tabela1[Motorista],Tabela1[[#This Row],[Motorista]])&" viagens")) -> 2 viagens | P19: 0.38333333 | Q19: 0.50694444 | R19: 13;15 | S19: Impresso | T19: =IF(OR(Tabela1[[#This Row],[Entrada]]="",Tabela1[[#This Row],[Saída]]=""), "", Tabela1[[#This Row],[Saída]]-Tabela1[[#This Row],[Entrada]]) -> #VALUE! | U19: =IF(OR('Controle de CT'!$R19= "", 'Controle de CT'!$P19= ""), "", 'Controle de CT'!$R19-'Controle de CT'!$P19) -> #VALUE!
K20: 46063 | L20: Benedito Gomes | M20: =IF(Tabela1[[#This Row],[Motorista]]="","",IFERROR(_xlfn.XLOOKUP(Tabela1[[#This Row],[Motorista]],Base!A:A,Base!B:B),"")) -> CIF | N20: =IF(R20<>"","Finalizado", IF(Q20<>"","Fila de Carregamento", IF(P20<>"","Aguardando Entrada",""))) -> Finalizado | O20: =IF(Tabela1[[#This Row],[Motorista]]="","",IF(COUNTIFS(Tabela1[Data],Tabela1[[#This Row],[Data]],Tabela1[Motorista],Tabela1[[#This Row],[Motorista]])=1,"1 viagem",COUNTIFS(Tabela1[Data],Tabela1[[#This Row],[Data]],Tabela1[Motorista],Tabela1[[#This Row],[Motorista]])&" viagens")) -> 2 viagens | P20: 0.38888889 | Q20: 0.39583333 | R20: 0.44444444 | S20: Impresso | T20: =IF(OR(Tabela1[[#This Row],[Entrada]]="",Tabela1[[#This Row],[Saída]]=""), "", Tabela1[[#This Row],[Saída]]-Tabela1[[#This Row],[Entrada]]) -> 0.048611111 | U20: =IF(OR('Controle de CT'!$R20= "", 'Controle de CT'!$P20= ""), "", 'Controle de CT'!$R20-'Controle de CT'!$P20) -> 0.055555556
K21: 46063 | L21: Ismael Souza Da Silva | M21: =IF(Tabela1[[#This Row],[Motorista]]="","",IFERROR(_xlfn.XLOOKUP(Tabela1[[#This Row],[Motorista]],Base!A:A,Base!B:B),"")) -> CIF | N21: =IF(R21<>"","Finalizado", IF(Q21<>"","Fila de Carregamento", IF(P21<>"","Aguardando Entrada",""))) -> Finalizado | O21: =IF(Tabela1[[#This Row],[Motorista]]="","",IF(COUNTIFS(Tabela1[Data],Tabela1[[#This Row],[Data]],Tabela1[Motorista],Tabela1[[#This Row],[Motorista]])=1,"1 viagem",COUNTIFS(Tabela1[Data],Tabela1[[#This Row],[Data]],Tabela1[Motorista],Tabela1[[#This Row],[Motorista]])&" viagens")) -> 1 viagem | P21: 0.39236111 | Q21: 0.40972222 | R21: 0.45138889 | S21: Impresso | T21: =IF(OR(Tabela1[[#This Row],[Entrada]]="",Tabela1[[#This Row],[Saída]]=""), "", Tabela1[[#This Row],[Saída]]-Tabela1[[#This Row],[Entrada]]) -> 0.041666667 | U21: =IF(OR('Controle de CT'!$R21= "", 'Controle de CT'!$P21= ""), "", 'Controle de CT'!$R21-'Controle de CT'!$P21) -> 0.059027778
K22: 46063 | L22: David dos Santos | M22: =IF(Tabela1[[#This Row],[Motorista]]="","",IFERROR(_xlfn.XLOOKUP(Tabela1[[#This Row],[Motorista]],Base!A:A,Base!B:B),"")) -> FOB | N22: =IF(R22<>"","Finalizado", IF(Q22<>"","Fila de Carregamento", IF(P22<>"","Aguardando Entrada",""))) -> Finalizado | O22: =IF(Tabela1[[#This Row],[Motorista]]="","",IF(COUNTIFS(Tabela1[Data],Tabela1[[#This Row],[Data]],Tabela1[Motorista],Tabela1[[#This Row],[Motorista]])=1,"1 viagem",COUNTIFS(Tabela1[Data],Tabela1[[#This Row],[Data]],Tabela1[Motorista],Tabela1[[#This Row],[Motorista]])&" viagens")) -> 2 viagens | P22: 0.44097222 | Q22: 0.4625 | R22: 0.50555556 | S22: Impresso | T22: =IF(OR(Tabela1[[#This Row],[Entrada]]="",Tabela1[[#This Row],[Saída]]=""), "", Tabela1[[#This Row],[Saída]]-Tabela1[[#This Row],[Entrada]]) -> 0.043055556 | U22: =IF(OR('Controle de CT'!$R22= "", 'Controle de CT'!$P22= ""), "", 'Controle de CT'!$R22-'Controle de CT'!$P22) -> 0.064583333
K23: 46063 | L23: Marielson De Oliveira | M23: =IF(Tabela1[[#This Row],[Motorista]]="","",IFERROR(_xlfn.XLOOKUP(Tabela1[[#This Row],[Motorista]],Base!A:A,Base!B:B),"")) -> FOB | N23: =IF(R23<>"","Finalizado", IF(Q23<>"","Fila de Carregamento", IF(P23<>"","Aguardando Entrada",""))) -> Finalizado | O23: =IF(Tabela1[[#This Row],[Motorista]]="","",IF(COUNTIFS(Tabela1[Data],Tabela1[[#This Row],[Data]],Tabela1[Motorista],Tabela1[[#This Row],[Motorista]])=1,"1 viagem",COUNTIFS(Tabela1[Data],Tabela1[[#This Row],[Data]],Tabela1[Motorista],Tabela1[[#This Row],[Motorista]])&" viagens")) -> 2 viagens | P23: 0.47430556 | Q23: 0.50763889 | R23: 0.54375 | S23: Impresso | T23: =IF(OR(Tabela1[[#This Row],[Entrada]]="",Tabela1[[#This Row],[Saída]]=""), "", Tabela1[[#This Row],[Saída]]-Tabela1[[#This Row],[Entrada]]) -> 0.036111111 | U23: =IF(OR('Controle de CT'!$R23= "", 'Controle de CT'!$P23= ""), "", 'Controle de CT'!$R23-'Controle de CT'!$P23) -> 0.069444444
K24: 46063 | L24: Juan Ricardo | M24: =IF(Tabela1[[#This Row],[Motorista]]="","",IFERROR(_xlfn.XLOOKUP(Tabela1[[#This Row],[Motorista]],Base!A:A,Base!B:B),"")) -> FOB | N24: =IF(R24<>"","Finalizado", IF(Q24<>"","Fila de Carregamento", IF(P24<>"","Aguardando Entrada",""))) -> Finalizado | O24: =IF(Tabela1[[#This Row],[Motorista]]="","",IF(COUNTIFS(Tabela1[Data],Tabela1[[#This Row],[Data]],Tabela1[Motorista],Tabela1[[#This Row],[Motorista]])=1,"1 viagem",COUNTIFS(Tabela1[Data],Tabela1[[#This Row],[Data]],Tabela1[Motorista],Tabela1[[#This Row],[Motorista]])&" viagens")) -> 1 viagem | P24: 0.51944444 | Q24: 0.54652778 | R24: 0.57013889 | S24: Impresso | T24: =IF(OR(Tabela1[[#This Row],[Entrada]]="",Tabela1[[#This Row],[Saída]]=""), "", Tabela1[[#This Row],[Saída]]-Tabela1[[#This Row],[Entrada]]) -> 0.023611111 | U24: =IF(OR('Controle de CT'!$R24= "", 'Controle de CT'!$P24= ""), "", 'Controle de CT'!$R24-'Controle de CT'!$P24) -> 0.050694444
K25: 46063 | L25: Denir Lucena | M25: =IF(Tabela1[[#This Row],[Motorista]]="","",IFERROR(_xlfn.XLOOKUP(Tabela1[[#This Row],[Motorista]],Base!A:A,Base!B:B),"")) -> Transferência | N25: =IF(R25<>"","Finalizado", IF(Q25<>"","Fila de Carregamento", IF(P25<>"","Aguardando Entrada",""))) -> Fila de Carregamento | O25: =IF(Tabela1[[#This Row],[Motorista]]="","",IF(COUNTIFS(Tabela1[Data],Tabela1[[#This Row],[Data]],Tabela1[Motorista],Tabela1[[#This Row],[Motorista]])=1,"1 viagem",COUNTIFS(Tabela1[Data],Tabela1[[#This Row],[Data]],Tabela1[Motorista],Tabela1[[#This Row],[Motorista]])&" viagens")) -> 1 viagem | P25: 0.54166667 | Q25: 0.54513889 | S25: Pendente | T25: =IF(OR(Tabela1[[#This Row],[Entrada]]="",Tabela1[[#This Row],[Saída]]=""), "", Tabela1[[#This Row],[Saída]]-Tabela1[[#This Row],[Entrada]]) | U25: =IF(OR('Controle de CT'!$R25= "", 'Controle de CT'!$P25= ""), "", 'Controle de CT'!$R25-'Controle de CT'!$P25)
K26: 46063 | L26: Francisco Nonato | M26: =IF(Tabela1[[#This Row],[Motorista]]="","",IFERROR(_xlfn.XLOOKUP(Tabela1[[#This Row],[Motorista]],Base!A:A,Base!B:B),"")) -> FOB | N26: =IF(R26<>"","Finalizado", IF(Q26<>"","Fila de Carregamento", IF(P26<>"","Aguardando Entrada",""))) -> Fila de Carregamento | O26: =IF(Tabela1[[#This Row],[Motorista]]="","",IF(COUNTIFS(Tabela1[Data],Tabela1[[#This Row],[Data]],Tabela1[Motorista],Tabela1[[#This Row],[Motorista]])=1,"1 viagem",COUNTIFS(Tabela1[Data],Tabela1[[#This Row],[Data]],Tabela1[Motorista],Tabela1[[#This Row],[Motorista]])&" viagens")) -> 1 viagem | P26: 0.53819444 | Q26: 0.55138889 | S26: Pendente | T26: =IF(OR(Tabela1[[#This Row],[Entrada]]="",Tabela1[[#This Row],[Saída]]=""), "", Tabela1[[#This Row],[Saída]]-Tabela1[[#This Row],[Entrada]]) | U26: =IF(OR('Controle de CT'!$R26= "", 'Controle de CT'!$P26= ""), "", 'Controle de CT'!$R26-'Controle de CT'!$P26)
K27: 46063 | L27: Jose Osvaldir Queiroz | M27: =IF(Tabela1[[#This Row],[Motorista]]="","",IFERROR(_xlfn.XLOOKUP(Tabela1[[#This Row],[Motorista]],Base!A:A,Base!B:B),"")) -> FOB | N27: =IF(R27<>"","Finalizado", IF(Q27<>"","Fila de Carregamento", IF(P27<>"","Aguardando Entrada",""))) -> Fila de Carregamento | O27: =IF(Tabela1[[#This Row],[Motorista]]="","",IF(COUNTIFS(Tabela1[Data],Tabela1[[#This Row],[Data]],Tabela1[Motorista],Tabela1[[#This Row],[Motorista]])=1,"1 viagem",COUNTIFS(Tabela1[Data],Tabela1[[#This Row],[Data]],Tabela1[Motorista],Tabela1[[#This Row],[Motorista]])&" viagens")) -> 2 viagens | P27: 0.54652778 | Q27: 0.55833333 | S27: Pendente | T27: =IF(OR(Tabela1[[#This Row],[Entrada]]="",Tabela1[[#This Row],[Saída]]=""), "", Tabela1[[#This Row],[Saída]]-Tabela1[[#This Row],[Entrada]]) | U27: =IF(OR('Controle de CT'!$R27= "", 'Controle de CT'!$P27= ""), "", 'Controle de CT'!$R27-'Controle de CT'!$P27)
K28: 46063 | L28: Rosiney de Cruz de Souza | M28: =IF(Tabela1[[#This Row],[Motorista]]="","",IFERROR(_xlfn.XLOOKUP(Tabela1[[#This Row],[Motorista]],Base!A:A,Base!B:B),"")) -> RZD | N28: =IF(R28<>"","Finalizado", IF(Q28<>"","Fila de Carregamento", IF(P28<>"","Aguardando Entrada",""))) -> Aguardando Entrada | O28: =IF(Tabela1[[#This Row],[Motorista]]="","",IF(COUNTIFS(Tabela1[Data],Tabela1[[#This Row],[Data]],Tabela1[Motorista],Tabela1[[#This Row],[Motorista]])=1,"1 viagem",COUNTIFS(Tabela1[Data],Tabela1[[#This Row],[Data]],Tabela1[Motorista],Tabela1[[#This Row],[Motorista]])&" viagens")) -> 1 viagem | P28: 0.61388889 | T28: =IF(OR(Tabela1[[#This Row],[Entrada]]="",Tabela1[[#This Row],[Saída]]=""), "", Tabela1[[#This Row],[Saída]]-Tabela1[[#This Row],[Entrada]]) | U28: =IF(OR('Controle de CT'!$R28= "", 'Controle de CT'!$P28= ""), "", 'Controle de CT'!$R28-'Controle de CT'!$P28)
K29: 46063 | L29: Jose Rogerio | M29: =IF(Tabela1[[#This Row],[Motorista]]="","",IFERROR(_xlfn.XLOOKUP(Tabela1[[#This Row],[Motorista]],Base!A:A,Base!B:B),"")) -> Transferência | N29: =IF(R29<>"","Finalizado", IF(Q29<>"","Fila de Carregamento", IF(P29<>"","Aguardando Entrada",""))) -> Aguardando Entrada | O29: =IF(Tabela1[[#This Row],[Motorista]]="","",IF(COUNTIFS(Tabela1[Data],Tabela1[[#This Row],[Data]],Tabela1[Motorista],Tabela1[[#This Row],[Motorista]])=1,"1 viagem",COUNTIFS(Tabela1[Data],Tabela1[[#This Row],[Data]],Tabela1[Motorista],Tabela1[[#This Row],[Motorista]])&" viagens")) -> 1 viagem | P29: 0.65902778 | T29: =IF(OR(Tabela1[[#This Row],[Entrada]]="",Tabela1[[#This Row],[Saída]]=""), "", Tabela1[[#This Row],[Saída]]-Tabela1[[#This Row],[Entrada]]) | U29: =IF(OR('Controle de CT'!$R29= "", 'Controle de CT'!$P29= ""), "", 'Controle de CT'!$R29-'Controle de CT'!$P29)
K30: 46063 | L30: Kalebe Oliveira da Silva | M30: =IF(Tabela1[[#This Row],[Motorista]]="","",IFERROR(_xlfn.XLOOKUP(Tabela1[[#This Row],[Motorista]],Base!A:A,Base!B:B),"")) -> FOB | N30: =IF(R30<>"","Finalizado", IF(Q30<>"","Fila de Carregamento", IF(P30<>"","Aguardando Entrada",""))) -> Finalizado | O30: =IF(Tabela1[[#This Row],[Motorista]]="","",IF(COUNTIFS(Tabela1[Data],Tabela1[[#This Row],[Data]],Tabela1[Motorista],Tabela1[[#This Row],[Motorista]])=1,"1 viagem",COUNTIFS(Tabela1[Data],Tabela1[[#This Row],[Data]],Tabela1[Motorista],Tabela1[[#This Row],[Motorista]])&" viagens")) -> 2 viagens | P30: 0.5625 | Q30: 0.58333333 | R30: 0.66597222 | S30: Impresso | T30: =IF(OR(Tabela1[[#This Row],[Entrada]]="",Tabela1[[#This Row],[Saída]]=""), "", Tabela1[[#This Row],[Saída]]-Tabela1[[#This Row],[Entrada]]) -> 0.082638889 | U30: =IF(OR('Controle de CT'!$R30= "", 'Controle de CT'!$P30= ""), "", 'Controle de CT'!$R30-'Controle de CT'!$P30) -> 0.10347222
K31: 46063 | L31: Andre Pereira de Oliveira | M31: =IF(Tabela1[[#This Row],[Motorista]]="","",IFERROR(_xlfn.XLOOKUP(Tabela1[[#This Row],[Motorista]],Base!A:A,Base!B:B),"")) -> FOB | N31: =IF(R31<>"","Finalizado", IF(Q31<>"","Fila de Carregamento", IF(P31<>"","Aguardando Entrada",""))) -> Aguardando Entrada | O31: =IF(Tabela1[[#This Row],[Motorista]]="","",IF(COUNTIFS(Tabela1[Data],Tabela1[[#This Row],[Data]],Tabela1[Motorista],Tabela1[[#This Row],[Motorista]])=1,"1 viagem",COUNTIFS(Tabela1[Data],Tabela1[[#This Row],[Data]],Tabela1[Motorista],Tabela1[[#This Row],[Motorista]])&" viagens")) -> 2 viagens | P31: 0.68472222 | T31: =IF(OR(Tabela1[[#This Row],[Entrada]]="",Tabela1[[#This Row],[Saída]]=""), "", Tabela1[[#This Row],[Saída]]-Tabela1[[#This Row],[Entrada]]) | U31: =IF(OR('Controle de CT'!$R31= "", 'Controle de CT'!$P31= ""), "", 'Controle de CT'!$R31-'Controle de CT'!$P31)
K32: 46064 | L32: David dos Santos | M32: =IF(Tabela1[[#This Row],[Motorista]]="","",IFERROR(_xlfn.XLOOKUP(Tabela1[[#This Row],[Motorista]],Base!A:A,Base!B:B),"")) -> FOB | N32: =IF(R32<>"","Finalizado", IF(Q32<>"","Fila de Carregamento", IF(P32<>"","Aguardando Entrada",""))) -> Finalizado | O32: =IF(Tabela1[[#This Row],[Motorista]]="","",IF(COUNTIFS(Tabela1[Data],Tabela1[[#This Row],[Data]],Tabela1[Motorista],Tabela1[[#This Row],[Motorista]])=1,"1 viagem",COUNTIFS(Tabela1[Data],Tabela1[[#This Row],[Data]],Tabela1[Motorista],Tabela1[[#This Row],[Motorista]])&" viagens")) -> 2 viagens | P32: 0.25277778 | Q32: 0.29444444 | R32: 0.33333333 | S32: Impresso | T32: =IF(OR(Tabela1[[#This Row],[Entrada]]="",Tabela1[[#This Row],[Saída]]=""), "", Tabela1[[#This Row],[Saída]]-Tabela1[[#This Row],[Entrada]]) -> 0.038888889 | U32: =IF(OR('Controle de CT'!$R32= "", 'Controle de CT'!$P32= ""), "", 'Controle de CT'!$R32-'Controle de CT'!$P32) -> 0.080555556
K33: 46064 | L33: Marielson De Oliveira | M33: =IF(Tabela1[[#This Row],[Motorista]]="","",IFERROR(_xlfn.XLOOKUP(Tabela1[[#This Row],[Motorista]],Base!A:A,Base!B:B),"")) -> FOB | N33: =IF(R33<>"","Finalizado", IF(Q33<>"","Fila de Carregamento", IF(P33<>"","Aguardando Entrada",""))) -> Finalizado | O33: =IF(Tabela1[[#This Row],[Motorista]]="","",IF(COUNTIFS(Tabela1[Data],Tabela1[[#This Row],[Data]],Tabela1[Motorista],Tabela1[[#This Row],[Motorista]])=1,"1 viagem",COUNTIFS(Tabela1[Data],Tabela1[[#This Row],[Data]],Tabela1[Motorista],Tabela1[[#This Row],[Motorista]])&" viagens")) -> 2 viagens | P33: 0.24791667 | Q33: 0.29236111 | R33: 0.33333333 | S33: Impresso | T33: =IF(OR(Tabela1[[#This Row],[Entrada]]="",Tabela1[[#This Row],[Saída]]=""), "", Tabela1[[#This Row],[Saída]]-Tabela1[[#This Row],[Entrada]]) -> 0.040972222 | U33: =IF(OR('Controle de CT'!$R33= "", 'Controle de CT'!$P33= ""), "", 'Controle de CT'!$R33-'Controle de CT'!$P33) -> 0.085416667
K34: 46064 | L34: Julio Cesar dos Santos | M34: =IF(Tabela1[[#This Row],[Motorista]]="","",IFERROR(_xlfn.XLOOKUP(Tabela1[[#This Row],[Motorista]],Base!A:A,Base!B:B),"")) -> FOB | N34: =IF(R34<>"","Finalizado", IF(Q34<>"","Fila de Carregamento", IF(P34<>"","Aguardando Entrada",""))) -> Finalizado | O34: =IF(Tabela1[[#This Row],[Motorista]]="","",IF(COUNTIFS(Tabela1[Data],Tabela1[[#This Row],[Data]],Tabela1[Motorista],Tabela1[[#This Row],[Motorista]])=1,"1 viagem",COUNTIFS(Tabela1[Data],Tabela1[[#This Row],[Data]],Tabela1[Motorista],Tabela1[[#This Row],[Motorista]])&" viagens")) -> 1 viagem | P34: 0.24930556 | Q34: 0.32361111 | R34: 3.3541667 | S34: Impresso | T34: =IF(OR(Tabela1[[#This Row],[Entrada]]="",Tabela1[[#This Row],[Saída]]=""), "", Tabela1[[#This Row],[Saída]]-Tabela1[[#This Row],[Entrada]]) -> 3.0305556 | U34: =IF(OR('Controle de CT'!$R34= "", 'Controle de CT'!$P34= ""), "", 'Controle de CT'!$R34-'Controle de CT'!$P34) -> 3.1048611
K35: 46064 | L35: Edney Freitas | M35: =IF(Tabela1[[#This Row],[Motorista]]="","",IFERROR(_xlfn.XLOOKUP(Tabela1[[#This Row],[Motorista]],Base!A:A,Base!B:B),"")) -> CIF | N35: =IF(R35<>"","Finalizado", IF(Q35<>"","Fila de Carregamento", IF(P35<>"","Aguardando Entrada",""))) -> Finalizado | O35: =IF(Tabela1[[#This Row],[Motorista]]="","",IF(COUNTIFS(Tabela1[Data],Tabela1[[#This Row],[Data]],Tabela1[Motorista],Tabela1[[#This Row],[Motorista]])=1,"1 viagem",COUNTIFS(Tabela1[Data],Tabela1[[#This Row],[Data]],Tabela1[Motorista],Tabela1[[#This Row],[Motorista]])&" viagens")) -> 2 viagens | P35: 0.27222222 | Q35: 0.27847222 | R35: 0.3375 | S35: Impresso | T35: =IF(OR(Tabela1[[#This Row],[Entrada]]="",Tabela1[[#This Row],[Saída]]=""), "", Tabela1[[#This Row],[Saída]]-Tabela1[[#This Row],[Entrada]]) -> 0.059027778 | U35: =IF(OR('Controle de CT'!$R35= "", 'Controle de CT'!$P35= ""), "", 'Controle de CT'!$R35-'Controle de CT'!$P35) -> 0.065277778
K36: 46064 | L36: Carlos Alberto Noronha | M36: =IF(Tabela1[[#This Row],[Motorista]]="","",IFERROR(_xlfn.XLOOKUP(Tabela1[[#This Row],[Motorista]],Base!A:A,Base!B:B),"")) -> CIF | N36: =IF(R36<>"","Finalizado", IF(Q36<>"","Fila de Carregamento", IF(P36<>"","Aguardando Entrada",""))) -> Finalizado | O36: =IF(Tabela1[[#This Row],[Motorista]]="","",IF(COUNTIFS(Tabela1[Data],Tabela1[[#This Row],[Data]],Tabela1[Motorista],Tabela1[[#This Row],[Motorista]])=1,"1 viagem",COUNTIFS(Tabela1[Data],Tabela1[[#This Row],[Data]],Tabela1[Motorista],Tabela1[[#This Row],[Motorista]])&" viagens")) -> 1 viagem | P36: 0.29166667 | Q36: 0.29583333 | R36: 0.38055556 | S36: Impresso | T36: =IF(OR(Tabela1[[#This Row],[Entrada]]="",Tabela1[[#This Row],[Saída]]=""), "", Tabela1[[#This Row],[Saída]]-Tabela1[[#This Row],[Entrada]]) -> 0.084722222 | U36: =IF(OR('Controle de CT'!$R36= "", 'Controle de CT'!$P36= ""), "", 'Controle de CT'!$R36-'Controle de CT'!$P36) -> 0.088888889
K37: 46064 | L37: Daiton De Lima Costa | M37: =IF(Tabela1[[#This Row],[Motorista]]="","",IFERROR(_xlfn.XLOOKUP(Tabela1[[#This Row],[Motorista]],Base!A:A,Base!B:B),"")) -> CIF | N37: =IF(R37<>"","Finalizado", IF(Q37<>"","Fila de Carregamento", IF(P37<>"","Aguardando Entrada",""))) -> Finalizado | O37: =IF(Tabela1[[#This Row],[Motorista]]="","",IF(COUNTIFS(Tabela1[Data],Tabela1[[#This Row],[Data]],Tabela1[Motorista],Tabela1[[#This Row],[Motorista]])=1,"1 viagem",COUNTIFS(Tabela1[Data],Tabela1[[#This Row],[Data]],Tabela1[Motorista],Tabela1[[#This Row],[Motorista]])&" viagens")) -> 1 viagem | P37: 0.28888889 | Q37: 0.29444444 | R37: 0.35416667 | S37: Impresso | T37: =IF(OR(Tabela1[[#This Row],[Entrada]]="",Tabela1[[#This Row],[Saída]]=""), "", Tabela1[[#This Row],[Saída]]-Tabela1[[#This Row],[Entrada]]) -> 0.059722222 | U37: =IF(OR('Controle de CT'!$R37= "", 'Controle de CT'!$P37= ""), "", 'Controle de CT'!$R37-'Controle de CT'!$P37) -> 0.065277778
K38: 46064 | L38: Raimundo Oderclei Cruz | M38: =IF(Tabela1[[#This Row],[Motorista]]="","",IFERROR(_xlfn.XLOOKUP(Tabela1[[#This Row],[Motorista]],Base!A:A,Base!B:B),"")) -> CIF | N38: =IF(R38<>"","Finalizado", IF(Q38<>"","Fila de Carregamento", IF(P38<>"","Aguardando Entrada",""))) -> Finalizado | O38: =IF(Tabela1[[#This Row],[Motorista]]="","",IF(COUNTIFS(Tabela1[Data],Tabela1[[#This Row],[Data]],Tabela1[Motorista],Tabela1[[#This Row],[Motorista]])=1,"1 viagem",COUNTIFS(Tabela1[Data],Tabela1[[#This Row],[Data]],Tabela1[Motorista],Tabela1[[#This Row],[Motorista]])&" viagens")) -> 1 viagem | P38: 0.28958333 | Q38: 0.32083333 | R38: 0.375 | S38: Impresso | T38: =IF(OR(Tabela1[[#This Row],[Entrada]]="",Tabela1[[#This Row],[Saída]]=""), "", Tabela1[[#This Row],[Saída]]-Tabela1[[#This Row],[Entrada]]) -> 0.054166667 | U38: =IF(OR('Controle de CT'!$R38= "", 'Controle de CT'!$P38= ""), "", 'Controle de CT'!$R38-'Controle de CT'!$P38) -> 0.085416667
K39: 46064 | L39: Wilmar Leao Filho | M39: =IF(Tabela1[[#This Row],[Motorista]]="","",IFERROR(_xlfn.XLOOKUP(Tabela1[[#This Row],[Motorista]],Base!A:A,Base!B:B),"")) | N39: =IF(R39<>"","Finalizado", IF(Q39<>"","Fila de Carregamento", IF(P39<>"","Aguardando Entrada",""))) -> Finalizado | O39: =IF(Tabela1[[#This Row],[Motorista]]="","",IF(COUNTIFS(Tabela1[Data],Tabela1[[#This Row],[Data]],Tabela1[Motorista],Tabela1[[#This Row],[Motorista]])=1,"1 viagem",COUNTIFS(Tabela1[Data],Tabela1[[#This Row],[Data]],Tabela1[Motorista],Tabela1[[#This Row],[Motorista]])&" viagens")) -> 1 viagem | P39: 0.29791667 | Q39: 0.32361111 | R39: 0.37083333 | S39: Impresso | T39: =IF(OR(Tabela1[[#This Row],[Entrada]]="",Tabela1[[#This Row],[Saída]]=""), "", Tabela1[[#This Row],[Saída]]-Tabela1[[#This Row],[Entrada]]) -> 0.047222222 | U39: =IF(OR('Controle de CT'!$R39= "", 'Controle de CT'!$P39= ""), "", 'Controle de CT'!$R39-'Controle de CT'!$P39) -> 0.072916667
K40: 46064 | L40: Francisco Pintos Nunes | M40: =IF(Tabela1[[#This Row],[Motorista]]="","",IFERROR(_xlfn.XLOOKUP(Tabela1[[#This Row],[Motorista]],Base!A:A,Base!B:B),"")) -> FOB | N40: =IF(R40<>"","Finalizado", IF(Q40<>"","Fila de Carregamento", IF(P40<>"","Aguardando Entrada",""))) -> Fila de Carregamento | O40: =IF(Tabela1[[#This Row],[Motorista]]="","",IF(COUNTIFS(Tabela1[Data],Tabela1[[#This Row],[Data]],Tabela1[Motorista],Tabela1[[#This Row],[Motorista]])=1,"1 viagem",COUNTIFS(Tabela1[Data],Tabela1[[#This Row],[Data]],Tabela1[Motorista],Tabela1[[#This Row],[Motorista]])&" viagens")) -> 1 viagem | P40: 0.30486111 | Q40: 0.42916667 | S40: Impresso | T40: =IF(OR(Tabela1[[#This Row],[Entrada]]="",Tabela1[[#This Row],[Saída]]=""), "", Tabela1[[#This Row],[Saída]]-Tabela1[[#This Row],[Entrada]]) | U40: =IF(OR('Controle de CT'!$R40= "", 'Controle de CT'!$P40= ""), "", 'Controle de CT'!$R40-'Controle de CT'!$P40)
K41: 46064 | L41: Said Pereira Rabelo | M41: =IF(Tabela1[[#This Row],[Motorista]]="","",IFERROR(_xlfn.XLOOKUP(Tabela1[[#This Row],[Motorista]],Base!A:A,Base!B:B),"")) -> FOB | N41: =IF(R41<>"","Finalizado", IF(Q41<>"","Fila de Carregamento", IF(P41<>"","Aguardando Entrada",""))) -> Finalizado | O41: =IF(Tabela1[[#This Row],[Motorista]]="","",IF(COUNTIFS(Tabela1[Data],Tabela1[[#This Row],[Data]],Tabela1[Motorista],Tabela1[[#This Row],[Motorista]])=1,"1 viagem",COUNTIFS(Tabela1[Data],Tabela1[[#This Row],[Data]],Tabela1[Motorista],Tabela1[[#This Row],[Motorista]])&" viagens")) -> 1 viagem | P41: 0.33888889 | Q41: 0.3625 | R41: 0.41319444 | S41: Impresso | T41: =IF(OR(Tabela1[[#This Row],[Entrada]]="",Tabela1[[#This Row],[Saída]]=""), "", Tabela1[[#This Row],[Saída]]-Tabela1[[#This Row],[Entrada]]) -> 0.050694444 | U41: =IF(OR('Controle de CT'!$R41= "", 'Controle de CT'!$P41= ""), "", 'Controle de CT'!$R41-'Controle de CT'!$P41) -> 0.074305556
K42: 46064 | L42: Andre Pereira de Oliveira | M42: =IF(Tabela1[[#This Row],[Motorista]]="","",IFERROR(_xlfn.XLOOKUP(Tabela1[[#This Row],[Motorista]],Base!A:A,Base!B:B),"")) -> FOB | N42: =IF(R42<>"","Finalizado", IF(Q42<>"","Fila de Carregamento", IF(P42<>"","Aguardando Entrada",""))) -> Finalizado | O42: =IF(Tabela1[[#This Row],[Motorista]]="","",IF(COUNTIFS(Tabela1[Data],Tabela1[[#This Row],[Data]],Tabela1[Motorista],Tabela1[[#This Row],[Motorista]])=1,"1 viagem",COUNTIFS(Tabela1[Data],Tabela1[[#This Row],[Data]],Tabela1[Motorista],Tabela1[[#This Row],[Motorista]])&" viagens")) -> 1 viagem | P42: 0.35763889 | Q42: 0.38541667 | R42: 0.43472222 | S42: Impresso | T42: =IF(OR(Tabela1[[#This Row],[Entrada]]="",Tabela1[[#This Row],[Saída]]=""), "", Tabela1[[#This Row],[Saída]]-Tabela1[[#This Row],[Entrada]]) -> 0.049305556 | U42: =IF(OR('Controle de CT'!$R42= "", 'Controle de CT'!$P42= ""), "", 'Controle de CT'!$R42-'Controle de CT'!$P42) -> 0.077083333
...

Sheet Base
A1: Motorista | B1: Tipo de Frete | C1: Frete | D1: Nota Fiscal | E1: Observação
A2: Abdiel ferreira | E2: Carregando na IPP
A3: Adriano Nunes Barbosa | B3: Transferência | E3: Produto parado
A4: Wilmar Leão
A5: Adriano Paz | B5: CIF | C5: CIF | D5: Impresso
A6: Alessandro Souza | B6: CIF | C6: FOB | D6: Pendente
A7: Valdemir Angelo | B7: RZD | C7: FOB
A8: Paulo GT
A9: Stanley
A10: Alexandre Gonçalves de Lima | B10: FOB
A11: ALUIZIO SOUZA VIEGAS | B11: Transferência
A12: Amâncio Gustavo de sales | B12: RZD
A13: Andre Pereira de Oliveira | B13: FOB
A14: Antonio Adailson | B14: CIF
A15: Antonio Carlos Da Silva Andrade | B15: FOB
A16: Antonio Carlos Lustosa | B16: FOB
A17: Augusto Cleber | B17: Transferência
A18: Benedito Gomes | B18: CIF
A19: Caio Victor Pessoa | B19: CIF
A20: Carlos Alberto Noronha | B20: CIF
A21: Carlos Antônio | B21: RZD
A22: Carlos Antonio dos Santos Melo
A23: Carlos Junior | B23: Transferência
A24: Carlos Magno | B24: FOB
A25: Celio Roberto Pimentel | B25: RZD
A26: Cesar Gomes Diniz | B26: RZD
A27: Cesar Soares | B27: Transferência
A28: Cleber Moreira | B28: FOB
A29: Daiton De Lima Costa | B29: CIF
A30: Daniel da Silva Rabelo | B30: RZD
A31: David dos Santos | B31: FOB
A32: Denilson Duarte | B32: FOB
A33: Denir Lucena | B33: Transferência
A34: Domilton Bezerra Severo | B34: Transferência
... A78: Josimar Nogueira | B78: FOB
A79: Josue Sales
A80: Juan Ricardo | B80: FOB
A81: Juan Walace De Oliveira Pantoja | B81: FOB
A82: Julio Cesar dos Santos | B82: FOB
A83: Kalebe Oliveira da Silva | B83: FOB
...
